<?xml version="1.0"?>
<robot name="hcc_robo">
  
  <material name="red">
    <color rgba="0 0 0.8 1"/>
  </material>

  <material name="white">
    <color rgba="1 1 1 1"/>
  </material>

  <link name="base_link">
    <visual>
      <geometry>
        <cylinder length="5" radius="2"/>
      </geometry>
      <origin rpy="0 0 0" xyz="0 0 2"/>
    </visual>
  </link>

  <joint name="base_to_hcc" type="prismatic">
    <parent link="base_link"/>
    <child link="hcc"/>
    <limit effort="100000" lower="0" upper="200" velocity="15"/>
    <axis xyz="1 0 0"/>
  </joint>

  <link name="hcc">
    <visual>
      <geometry>
        <cylinder length="5" radius="2"/>
      </geometry>
      <origin rpy="0 0 0" xyz="0 0 2"/>
    </visual>
  </link>

  <joint name="hcc_to_hcc_rear_boom" type="revolute">
    <parent link="hcc"/>
    <child link="hcc_rear_boom"/>
    <axis xyz="0 0 1"/>
    <origin xyz="0 0 0"/>
    <limit effort="1000.0" lower="0" upper="1.5" velocity="0.5"/>
  </joint>

  <link name="hcc_rear_boom">
    <visual>
      <geometry>
        <box size = "20 2 2"/>
      </geometry>
      <origin rpy="0 0 0" xyz="10 0 0"/>
      <material name="blue"/>
    </visual>
  </link>

  <joint name="hcc_rear_boom_to_end" type="revolute">
    <parent link="hcc_rear_boom"/>
    <child link="end"/>
    <axis xyz="0 0 1"/>
    <origin rpy="0 0 0" xyz="20 0 0"/>
    <limit effort="1000.0" lower="-0.5" upper="0.5" velocity="0.5"/>
  </joint>

  <link name="end">
    <visual>
      <geometry>
        <cylinder length="5" radius="2"/>
      </geometry>
      <origin rpy="0 0 0" xyz="0 0 0"/>
      <material name="blue"/>
    </visual>
  </link>

</robot>
